[2023-03-04 16:04:34,398, user] Exception(IntegrityError('23000', "[23000] [MySQL][ODBC 8.0(w) Driver][mysqld-8.0.31]Duplicate entry 'timo' for key 'users.ACCOUNT' (1062) (SQLExecDirectW)"))
[2023-03-04 16:06:34,426, user] Exception(IntegrityError('23000', "[23000] [MySQL][ODBC 8.0(w) Driver][mysqld-8.0.31]Duplicate entry 'timo' for key 'users.ACCOUNT' (1062) (SQLExecDirectW)"))
[2023-03-04 16:16:44,487, user] KeyError('name')
[2023-03-04 16:16:44,487, login] KeyError('name')
[2023-03-04 16:19:36,765, user] KeyError('name')
[2023-03-04 16:19:36,765, login] KeyError('name')
[2023-03-04 16:19:51,553, user] Exception(DatabaseError('Execution failed on sql \'\n                SELECT PASSWORD, SALT\n                WHERE ACCOUNT="timo"\n                \': (\'42S22\', "[42S22] [MySQL][ODBC 8.0(w) Driver][mysqld-8.0.31]Unknown column \'PASSWORD\' in \'field list\' (1054) (SQLExecDirectW)")'))
[2023-03-04 16:19:51,553, login] Exception(DatabaseError('Execution failed on sql \'\n                SELECT PASSWORD, SALT\n                WHERE ACCOUNT="timo"\n                \': (\'42S22\', "[42S22] [MySQL][ODBC 8.0(w) Driver][mysqld-8.0.31]Unknown column \'PASSWORD\' in \'field list\' (1054) (SQLExecDirectW)")'))
[2023-03-04 16:21:35,973, user] AttributeError("'Series' object has no attribute 'encode'")
[2023-03-04 16:21:35,973, login] AttributeError("'Series' object has no attribute 'encode'")
[2023-03-04 16:24:28,452, user] IndexError('index 0 is out of bounds for axis 0 with size 0')
[2023-03-04 16:24:28,452, login] IndexError('index 0 is out of bounds for axis 0 with size 0')
[2023-03-04 16:25:38,379, user] Exception('帳號或密碼錯誤')
[2023-03-04 16:25:38,379, login] Exception('帳號或密碼錯誤')
[2023-03-04 16:25:41,562, user] TypeError("'str' object is not callable")
[2023-03-04 16:25:41,562, login] TypeError("'str' object is not callable")
[2023-03-04 16:25:58,870, user] Exception('帳號或密碼錯誤')
[2023-03-04 16:25:58,870, login] Exception('帳號或密碼錯誤')
[2023-03-04 16:29:48,831, user] KeyError('ACCOUNT')
[2023-03-04 16:29:48,831, login] KeyError('ACCOUNT')
[2023-03-04 16:30:24,461, user] RuntimeError('You must initialize a JWTManager with this flask application before using this method')
[2023-03-04 16:30:24,461, login] RuntimeError('You must initialize a JWTManager with this flask application before using this method')
[2023-03-04 16:42:16,361, user] <BadRequest '400: Bad Request'>
[2023-03-04 16:42:16,361, login] <BadRequest '400: Bad Request'>
[2023-03-04 16:42:34,227, user] <BadRequest '400: Bad Request'>
[2023-03-04 16:42:34,227, login] <BadRequest '400: Bad Request'>
[2023-03-04 16:52:17,470, user] IndexError('index 0 is out of bounds for axis 0 with size 0')
[2023-03-04 16:52:17,470, login] IndexError('index 0 is out of bounds for axis 0 with size 0')
[2023-03-04 17:02:34,463, user] Exception('帳號或密碼錯誤')
[2023-03-04 17:02:34,463, login] Exception('帳號或密碼錯誤')
[2023-03-04 17:02:37,967, user] Exception('帳號或密碼錯誤')
[2023-03-04 17:02:37,967, login] Exception('帳號或密碼錯誤')
[2023-03-04 17:02:40,790, user] Exception('帳號或密碼錯誤')
[2023-03-04 17:02:40,790, login] Exception('帳號或密碼錯誤')
[2023-03-04 17:02:55,145, user] Exception('帳號或密碼錯誤')
[2023-03-04 17:02:55,145, login] Exception('帳號或密碼錯誤')
[2023-03-04 17:03:13,241, user] ConnectionError('Error 10061 connecting to localhost:6379. 無法連線，因為目標電腦拒絕連線。.')
[2023-03-04 17:03:13,241, login] ConnectionError('Error 10061 connecting to localhost:6379. 無法連線，因為目標電腦拒絕連線。.')
[2023-03-04 17:03:44,100, user] 127.0.0.1 - - [04/Mar/2023 17:03:44] code 400, message Bad request syntax ('*5')
[2023-03-04 17:03:44,100, login] 127.0.0.1 - - [04/Mar/2023 17:03:44] code 400, message Bad request syntax ('*5')
[2023-03-04 17:03:44,101, user] ConnectionError('Connection closed by server.')
[2023-03-04 17:03:44,101, login] ConnectionError('Connection closed by server.')
